<?xml version="1.0"?>
<robot name="wheel" xmlns:xacro="http://www.ros.org/wiki/xacro">
  <xacro:macro name="rubber_wheel" params="prefix parent *origin hq">
    <xacro:property name="wheel_radius" value="0.07" />
    <xacro:property name="wheel_width" value="0.025" />
    <xacro:property name="wheel_mass" value="6.0" />

    <joint name="${prefix}joint" type="continuous">
      <parent link="${parent}"/>
      <child link="${prefix}link"/>
      <xacro:insert_block name="origin" />
      <axis xyz="0 1 0" rpy="0 0 0" />
      <limit effort="100" velocity="100"/>
      <joint_properties damping="0.0" friction="0.1"/>
    </joint>
    <link name="${prefix}link">
      <visual>
        <origin xyz="0 0 0" rpy="${M_PI/2} 0 0" />
        <geometry>
          <cylinder length="${wheel_width}" radius="${wheel_radius}" />
        </geometry>
        <material name="darkgrey">
          <color rgba="0.2 0.2 0.2 1"/>
        </material>
      </visual>
      <collision>
        <origin xyz="0 0 0" rpy="${M_PI/2} 0 0" />
        <geometry>
          <cylinder length="${wheel_width}" radius="${wheel_radius}" />
        </geometry>
      </collision>
      <inertial>
        <mass value="${wheel_mass}" />
        <origin xyz="0 0 0" rpy="${M_PI/2} 0 0" />
        <xacro:cylinder_inertial mass="${wheel_mass}" radius="${wheel_radius}" height="${wheel_width}" />
      </inertial>
    </link>
    <gazebo reference="${prefix}link">
      <mu1>0.85</mu1>
      <mu2>0.85</mu2>
      <kp>1.0e12</kp>
      <kd>1.0e3</kd>
      <fdir1>0 0 1</fdir1>
      <material>Gazebo/Yellow</material>
      <turnGravityOff>false</turnGravityOff>
      <minDepth>0.001</minDepth>
    </gazebo>
    <transmission name="${prefix}transmission">
      <type>transmission_interface/SimpleTransmission</type>
      <joint name="${prefix}joint">
        <hardwareInterface>hardware_interface/VelocityJointInterface</hardwareInterface>
      </joint>
      <actuator name="${prefix}motor">
        <!-- <hardwareInterface>hardware_interface/VelocityJointInterface</hardwareInterface> -->
        <mechanicalReduction>1</mechanicalReduction>
          <motorTorqueConstant>20</motorTorqueConstant>
      </actuator>
    </transmission>
  </xacro:macro>
</robot>
