<?xml version="1.0"?>
<robot name="caster" xmlns:xacro="http://www.ros.org/wiki/xacro">

  <xacro:macro name="caster" params="prefix parent *origin hq">
    <!-- Caster support parameters -->
    <xacro:property name="caster_support_mass" value="1.5" /> <!-- in kg-->

    <!-- Caster wheel parameters -->
    <xacro:property name="caster_radius" value="0.0375" />
    <xacro:property name="caster_width" value="0.025" />
    <xacro:property name="caster_mass" value="0.3" /> <!-- in kg-->

    <!-- Caster wheel offset-->
    <xacro:property name="caster_wheel_offset_x" value="-0.024" />
    <xacro:property name="caster_wheel_offset_y" value="0.0" />
    <xacro:property name="caster_wheel_offset_z" value="-0.06266" />

    <xacro:macro name="cylinder_inertia" params="m r h">
      <inertia  ixx="${m*(3*r*r+h*h)/12}" ixy = "0" ixz = "0"
                iyy="${m*(3*r*r+h*h)/12}" iyz = "0"
                izz="${m*r*r/2}" />
    </xacro:macro>

    <!--CASTER SUPPORT -->
    <joint name="${prefix}support_joint" type="continuous">
      <xacro:insert_block name="origin" />
      <parent link="${parent}"/>
      <child link="${prefix}base_link"/>
      <axis xyz="0 0 1" />
      <dynamics damping="0.01" friction="0.1"/>
    </joint>
    <link name="${prefix}base_link">
      <visual>
        <origin xyz="0 0 0" rpy="0 0 0" />
        <geometry>
          <mesh filename="package://rbsherkan_description/meshes/wheels/castor_wheel.stl" scale="0.82 0.82 0.82"/>
        </geometry>
        <material name="darkgrey">
          <color rgba="0.2 0.2 0.2 1"/>
        </material>
      </visual>
      <inertial>
        <mass value="0.1" />
        <origin xyz="0 0 0" rpy="0 0 0" />
        <inertia ixx="0.001" ixy="0" ixz="0" iyy="0.001" iyz="0" izz="0.001" />
      </inertial>
    </link>

    <joint name="${prefix}joint" type="continuous">
      <origin xyz="${caster_wheel_offset_x} ${caster_wheel_offset_y} ${caster_wheel_offset_z}" rpy="0 0 0" />
      <parent link="${prefix}base_link"/>
      <child link="${prefix}link"/>
      <axis xyz="0 1 0"/>
      <dynamics damping="0.01" friction="0.1"/>
    </joint>
    <link name="${prefix}link">
      <!--visual>
        <origin xyz="0 0 0" rpy="${M_PI/2} 0 0" />
        <geometry>
          <cylinder radius="${caster_radius}" length="${caster_width}"/>
        </geometry>
      </visual-->
      <collision>
        <origin xyz="0 0 0" rpy="${M_PI/2} 0 0" />
        <geometry>
          <cylinder radius="${caster_radius}" length="${caster_width}"/>
        </geometry>
      </collision>
      <inertial>
        <mass value="${caster_mass}" />
        <origin xyz="0 0 0" rpy="${M_PI_4} 0 0" />
        <xacro:cylinder_inertia m="${caster_mass}" r="${caster_radius}" h="${caster_width}" />
      </inertial>
    </link>

    <gazebo reference="${prefix}support">
      <mu1>0.45</mu1>
      <mu2>0.45</mu2>
      <kp>2.75e7</kp>
      <kd>8.25e1</kd>
      <fdir1>0 0 1</fdir1>
      <maxContacts>4</maxContacts>
    </gazebo>
    <gazebo reference="${prefix}link">
      <mu1>0.9</mu1>
      <mu2>0.9</mu2>
      <kp>1.0e12</kp>
      <kd>1.0e0</kd>
      <fdir1>0 0 1</fdir1>
      <maxContacts>4</maxContacts>
      <minDepth>0.001</minDepth>
    </gazebo>

    <gazebo reference="${prefix}joint">
      <stopCfm value="0.0"/>
      <stopErp value="0.2"/>
      <fudgeFactor value="0.8"/>
    </gazebo>
 </xacro:macro>

</robot>
